Workbook

Sheet Sheet1
A1: Current Property Listings
A3: Date | B3: Listing Price | C3: Property Location | D3: County | E3: Avg Home Price | F3: Sales Agent | G3: Price Compared to Avg Home Price
A4: 45189 | B4: 69900 | C4: Boardson | D4: =VLOOKUP(Sheet1!$C4,City_CountyData[],2,0) -> Bon Homme | E4: =VLOOKUP(Sheet1!$C4,City_CountyData[],3,0) -> 323188 | F4: Grady | G4: =Sheet1!$B4-Sheet1!$E4 -> -253288
A5: 45013 | B5: 235000 | C5: Springfield | D5: =VLOOKUP(Sheet1!$C5,City_CountyData[],2,0) -> Bon Homme | E5: =VLOOKUP(Sheet1!$C5,City_CountyData[],3,0) -> 323188 | F5: Boone | G5: =Sheet1!$B5-Sheet1!$E5 -> -88188
B6: =SUBTOTAL(1,B4:B5) -> 152450 | D6: Bon Homme Average
A7: 45178 | B7: 498000 | C7: Aberdeen | D7: =VLOOKUP(Sheet1!$C7,City_CountyData[],2,0) -> Brown | E7: =VLOOKUP(Sheet1!$C7,City_CountyData[],3,0) -> 235241 | F7: Alvarez | G7: =Sheet1!$B7-Sheet1!$E7 -> 262759
A8: 45002 | B8: 420000 | C8: Aberdeen | D8: =VLOOKUP(Sheet1!$C8,City_CountyData[],2,0) -> Brown | E8: =VLOOKUP(Sheet1!$C8,City_CountyData[],3,0) -> 235241 | F8: Patel | G8: =Sheet1!$B8-Sheet1!$E8 -> 184759
A9: 44941 | B9: 299000 | C9: Aberdeen | D9: =VLOOKUP(Sheet1!$C9,City_CountyData[],2,0) -> Brown | E9: =VLOOKUP(Sheet1!$C9,City_CountyData[],3,0) -> 235241 | F9: Williams | G9: =Sheet1!$B9-Sheet1!$E9 -> 63759
A10: 45128 | B10: 239900 | C10: Aberdeen | D10: =VLOOKUP(Sheet1!$C10,City_CountyData[],2,0) -> Brown | E10: =VLOOKUP(Sheet1!$C10,City_CountyData[],3,0) -> 235241 | F10: Boone | G10: =Sheet1!$B10-Sheet1!$E10 -> 4659
A11: 45057 | B11: 129400 | C11: Aberdeen | D11: =VLOOKUP(Sheet1!$C11,City_CountyData[],2,0) -> Brown | E11: =VLOOKUP(Sheet1!$C11,City_CountyData[],3,0) -> 235241 | F11: Robinson | G11: =Sheet1!$B11-Sheet1!$E11 -> -105841
B12: =SUBTOTAL(1,B7:B11) -> 317260 | D12: Brown Average
A13: 45227 | B13: 467000 | C13: Chamberlain | D13: =VLOOKUP(Sheet1!$C13,City_CountyData[],2,0) -> Brule | E13: =VLOOKUP(Sheet1!$C13,City_CountyData[],3,0) -> 278201 | F13: Grady | G13: =Sheet1!$B13-Sheet1!$E13 -> 188799
A14: 45010 | B14: 387000 | C14: Chamberlain | D14: =VLOOKUP(Sheet1!$C14,City_CountyData[],2,0) -> Brule | E14: =VLOOKUP(Sheet1!$C14,City_CountyData[],3,0) -> 278201 | F14: Ford | G14: =Sheet1!$B14-Sheet1!$E14 -> 108799
B15: =SUBTOTAL(1,B13:B14) -> 427000 | D15: Brule Average
A16: 44982 | B16: 379900 | C16: Belle Fourche | D16: =VLOOKUP(Sheet1!$C16,City_CountyData[],2,0) -> Butte | E16: =VLOOKUP(Sheet1!$C16,City_CountyData[],3,0) -> 179453 | F16: Alvarez | G16: =Sheet1!$B16-Sheet1!$E16 -> 200447
A17: 45260 | B17: 526900 | C17: Cedarburg | D17: =VLOOKUP(Sheet1!$C17,City_CountyData[],2,0) -> Butte | E17: =VLOOKUP(Sheet1!$C17,City_CountyData[],3,0) -> 179453 | F17: Crenshaw | G17: =Sheet1!$B17-Sheet1!$E17 -> 347447
B18: =SUBTOTAL(1,B16:B17) -> 453400 | D18: Butte Average
A19: 45169 | B19: 46900 | C19: Fall City | D19: =VLOOKUP(Sheet1!$C19,City_CountyData[],2,0) -> Charles Mix | E19: =VLOOKUP(Sheet1!$C19,City_CountyData[],3,0) -> 188622 | F19: Vermeer | G19: =Sheet1!$B19-Sheet1!$E19 -> -141722
A20: 45162 | B20: 269000 | C20: Wagner | D20: =VLOOKUP(Sheet1!$C20,City_CountyData[],2,0) -> Charles Mix | E20: =VLOOKUP(Sheet1!$C20,City_CountyData[],3,0) -> 188622 | F20: Alvarez | G20: =Sheet1!$B20-Sheet1!$E20 -> 80378
A21: 45023 | B21: 104900 | C21: Wagner | D21: =VLOOKUP(Sheet1!$C21,City_CountyData[],2,0) -> Charles Mix | E21: =VLOOKUP(Sheet1!$C21,City_CountyData[],3,0) -> 188622 | F21: Vermeer | G21: =Sheet1!$B21-Sheet1!$E21 -> -83722
B22: =SUBTOTAL(1,B19:B21) -> 140266.67 | D22: Charles Mix Average
A23: 45196 | B23: 249500 | C23: Mason | D23: =VLOOKUP(Sheet1!$C23,City_CountyData[],2,0) -> Clay | E23: =VLOOKUP(Sheet1!$C23,City_CountyData[],3,0) -> 227418 | F23: Boone | G23: =Sheet1!$B23-Sheet1!$E23 -> 22082
A24: 45186 | B24: 89900 | C24: Mason | D24: =VLOOKUP(Sheet1!$C24,City_CountyData[],2,0) -> Clay | E24: =VLOOKUP(Sheet1!$C24,City_CountyData[],3,0) -> 227418 | F24: Nguyen | G24: =Sheet1!$B24-Sheet1!$E24 -> -137518
A25: 44969 | B25: 105000 | C25: Vermillion | D25: =VLOOKUP(Sheet1!$C25,City_CountyData[],2,0) -> Clay | E25: =VLOOKUP(Sheet1!$C25,City_CountyData[],3,0) -> 227418 | F25: Grady | G25: =Sheet1!$B25-Sheet1!$E25 -> -122418
B26: =SUBTOTAL(1,B23:B25) -> 148133.33 | D26: Clay Average
A27: 45261 | B27: 314000 | C27: Fountainville | D27: =VLOOKUP(Sheet1!$C27,City_CountyData[],2,0) -> Davison | E27: =VLOOKUP(Sheet1!$C27,City_CountyData[],3,0) -> 506274 | F27: Wu | G27: =Sheet1!$B27-Sheet1!$E27 -> -192274
A28: 45067 | B28: 590000 | C28: Mitchell | D28: =VLOOKUP(Sheet1!$C28,City_CountyData[],2,0) -> Davison | E28: =VLOOKUP(Sheet1!$C28,City_CountyData[],3,0) -> 506274 | F28: Alvarez | G28: =Sheet1!$B28-Sheet1!$E28 -> 83726
A29: 44954 | B29: 287500 | C29: Mitchell | D29: =VLOOKUP(Sheet1!$C29,City_CountyData[],2,0) -> Davison | E29: =VLOOKUP(Sheet1!$C29,City_CountyData[],3,0) -> 506274 | F29: Ogea | G29: =Sheet1!$B29-Sheet1!$E29 -> -218774
A30: 45004 | B30: 280000 | C30: Mitchell | D30: =VLOOKUP(Sheet1!$C30,City_CountyData[],2,0) -> Davison | E30: =VLOOKUP(Sheet1!$C30,City_CountyData[],3,0) -> 506274 | F30: Alvarez | G30: =Sheet1!$B30-Sheet1!$E30 -> -226274
A31: 45130 | B31: 118000 | C31: Mitchell | D31: =VLOOKUP(Sheet1!$C31,City_CountyData[],2,0) -> Davison | E31: =VLOOKUP(Sheet1!$C31,City_CountyData[],3,0) -> 506274 | F31: Crenshaw | G31: =Sheet1!$B31-Sheet1!$E31 -> -388274
A32: 45156 | B32: 298000 | C32: Watertown | D32: =VLOOKUP(Sheet1!$C32,City_CountyData[],2,0) -> Davison | E32: =VLOOKUP(Sheet1!$C32,City_CountyData[],3,0) -> 506274 | F32: Patel | G32: =Sheet1!$B32-Sheet1!$E32 -> -208274
B33: =SUBTOTAL(1,B27:B32) -> 314583.33 | D33: Davison Average
A34: 44988 | B34: 230000 | C34: Milbank | D34: =VLOOKUP(Sheet1!$C34,City_CountyData[],2,0) -> Grant | E34: =VLOOKUP(Sheet1!$C34,City_CountyData[],3,0) -> 207661 | F34: Ford | G34: =Sheet1!$B34-Sheet1!$E34 -> 22339
A35: 45218 | B35: 179000 | C35: Milbank | D35: =VLOOKUP(Sheet1!$C35,City_CountyData[],2,0) -> Grant | E35: =VLOOKUP(Sheet1!$C35,City_CountyData[],3,0) -> 207661 | F35: Boone | G35: =Sheet1!$B35-Sheet1!$E35 -> -28661
A36: 45092 | B36: 112800 | C36: Milbank | D36: =VLOOKUP(Sheet1!$C36,City_CountyData[],2,0) -> Grant | E36: =VLOOKUP(Sheet1!$C36,City_CountyData[],3,0) -> 207661 | F36: Alvarez | G36: =Sheet1!$B36-Sheet1!$E36 -> -94861
B37: =SUBTOTAL(1,B34:B36) -> 173933.33 | D37: Grant Average
A38: 45249 | B38: 173000 | C38: Germantown | D38: =VLOOKUP(Sheet1!$C38,City_CountyData[],2,0) -> Lawrence | E38: =VLOOKUP(Sheet1!$C38,City_CountyData[],3,0) -> 197560 | F38: Locklear | G38: =Sheet1!$B38-Sheet1!$E38 -> -24560
A39: 45118 | B39: 269000 | C39: Lead | D39: =VLOOKUP(Sheet1!$C39,City_CountyData[],2,0) -> Lawrence | E39: =VLOOKUP(Sheet1!$C39,City_CountyData[],3,0) -> 197560 | F39: Wu | G39: =Sheet1!$B39-Sheet1!$E39 -> 71440
A40: 44996 | B40: 265000 | C40: Lead | D40: =VLOOKUP(Sheet1!$C40,City_CountyData[],2,0) -> Lawrence | E40: =VLOOKUP(Sheet1!$C40,City_CountyData[],3,0) -> 197560 | F40: Boone | G40: =Sheet1!$B40-Sheet1!$E40 -> 67440
A41: 45281 | B41: 141900 | C41: Lead | D41: =VLOOKUP(Sheet1!$C41,City_CountyData[],2,0) -> Lawrence | E41: =VLOOKUP(Sheet1!$C41,City_CountyData[],3,0) -> 197560 | F41: Nguyen | G41: =Sheet1!$B41-Sheet1!$E41 -> -55660
...

Sheet Sheet2
A1: City | B1: County | C1: Avg Home Price
A2: Aberdeen | B2: Brown | C2: 235241
A3: Belle Fourche | B3: Butte | C3: 179453
A4: Birmingham | B4: Lincoln | C4: 298177
A5: Boardson | B5: Bon Homme | C5: 323188
A6: Box Elder | B6: Pennington | C6: 266875
A7: Cedarburg | B7: Butte | C7: 179453
A8: Chamberlain | B8: Brule | C8: 278201
A9: Dakota Dunes | B9: Union | C9: 339197
A10: Dayton | B10: Union | C10: 339197
A11: Fall City | B11: Charles Mix | C11: 188622
A12: Fountainville | B12: Davison | C12: 506274
A13: Garretson | B13: Minnehaha | C13: 388497
... A35: Yankton | B35: Yankton | C35: 256076
