Workbook

Sheet Commissions
A1: Date of Sale | B1: Sales Agent | C1: Sale Price | D1: Commission Earned
A2: 45200 | B2: Alvarez | C2: 159500 | D2: =IF(C2>300000,C2*0.01,C2*0.02) -> 3190
A3: 45269 | B3: Alvarez | C3: 498000 | D3: =IF(C3>300000,C3*0.01,C3*0.02) -> 4980
A4: 45275 | B4: Alvarez | C4: 112800 | D4: =IF(C4>300000,C4*0.01,C4*0.02) -> 2256
A5: 45279 | B5: Alvarez | C5: 280000 | D5: =IF(C5>300000,C5*0.01,C5*0.02) -> 5600
A6: 45287 | B6: Alvarez | C6: 284000 | D6: =IF(C6>300000,C6*0.01,C6*0.02) -> 5680
B7: Alvarez Total | D7: =SUBTOTAL(9,D2:D6) -> 21706
A8: 45218 | B8: Boone | C8: 179000 | D8: =IF(C8>300000,C8*0.01,C8*0.02) -> 3580
A9: 45246 | B9: Boone | C9: 357000 | D9: =IF(C9>300000,C9*0.01,C9*0.02) -> 3570
A10: 45271 | B10: Boone | C10: 265000 | D10: =IF(C10>300000,C10*0.01,C10*0.02) -> 5300
A11: 45287 | B11: Boone | C11: 249500 | D11: =IF(C11>300000,C11*0.01,C11*0.02) -> 4990
A12: 45288 | B12: Boone | C12: 235000 | D12: =IF(C12>300000,C12*0.01,C12*0.02) -> 4700
B13: Boone Total | D13: =SUBTOTAL(9,D8:D12) -> 22140
A14: 45242 | B14: Grady | C14: 105000 | D14: =IF(C14>300000,C14*0.01,C14*0.02) -> 2100
A15: 45280 | B15: Grady | C15: 69900 | D15: =IF(C15>300000,C15*0.01,C15*0.02) -> 1398
A16: 45282 | B16: Grady | C16: 245000 | D16: =IF(C16>300000,C16*0.01,C16*0.02) -> 4900
B17: Grady Total | D17: =SUBTOTAL(9,D14:D16) -> 8398
A18: 45214 | B18: Locklear | C18: 346000 | D18: =IF(C18>300000,C18*0.01,C18*0.02) -> 3460
A19: 45245 | B19: Locklear | C19: 265000 | D19: =IF(C19>300000,C19*0.01,C19*0.02) -> 5300
A20: 45249 | B20: Locklear | C20: 173000 | D20: =IF(C20>300000,C20*0.01,C20*0.02) -> 3460
A21: 45266 | B21: Locklear | C21: 63900 | D21: =IF(C21>300000,C21*0.01,C21*0.02) -> 1278
A22: 45268 | B22: Locklear | C22: 261000 | D22: =IF(C22>300000,C22*0.01,C22*0.02) -> 5220
B23: Locklear Total | D23: =SUBTOTAL(9,D18:D22) -> 18718
A24: 45217 | B24: Nguyen | C24: 439000 | D24: =IF(C24>300000,C24*0.01,C24*0.02) -> 4390
A25: 45277 | B25: Nguyen | C25: 89900 | D25: =IF(C25>300000,C25*0.01,C25*0.02) -> 1798
A26: 45281 | B26: Nguyen | C26: 141900 | D26: =IF(C26>300000,C26*0.01,C26*0.02) -> 2838
A27: 45291 | B27: Nguyen | C27: 635000 | D27: =IF(C27>300000,C27*0.01,C27*0.02) -> 6350
B28: Nguyen Total | D28: =SUBTOTAL(9,D24:D27) -> 15376
A29: 45248 | B29: Patel | C29: 298000 | D29: =IF(C29>300000,C29*0.01,C29*0.02) -> 5960
A30: 45267 | B30: Patel | C30: 207000 | D30: =IF(C30>300000,C30*0.01,C30*0.02) -> 4140
A31: 45277 | B31: Patel | C31: 420000 | D31: =IF(C31>300000,C31*0.01,C31*0.02) -> 4200
B32: Patel Total | D32: =SUBTOTAL(9,D29:D31) -> 14300
A33: 45209 | B33: Robinson | C33: 395000 | D33: =IF(C33>300000,C33*0.01,C33*0.02) -> 3950
A34: 45241 | B34: Robinson | C34: 129400 | D34: =IF(C34>300000,C34*0.01,C34*0.02) -> 2588
A35: 45248 | B35: Robinson | C35: 364900 | D35: =IF(C35>300000,C35*0.01,C35*0.02) -> 3649
A36: 45269 | B36: Robinson | C36: 74900 | D36: =IF(C36>300000,C36*0.01,C36*0.02) -> 1498
B37: Robinson Total | D37: =SUBTOTAL(9,D33:D36) -> 11685
A38: 45214 | B38: Williams | C38: 299000 | D38: =IF(C38>300000,C38*0.01,C38*0.02) -> 5980
B39: Williams Total | D39: =SUBTOTAL(9,D38:D38) -> 5980
A40: 45242 | B40: Wu | C40: 599000 | D40: =IF(C40>300000,C40*0.01,C40*0.02) -> 5990
...

Sheet Chart
A1: Sales Agent
A2: Alvarez | B2: =Commissions!D7 -> 21706
A3: Boone | B3: =Commissions!D13 -> 22140
A4: Grady | B4: =Commissions!D17 -> 8398
A5: Locklear | B5: =Commissions!D23 -> 18718
A6: Nguyen | B6: =Commissions!D28 -> 15376
A7: Patel | B7: =Commissions!D32 -> 14300
A8: Robinson | B8: =Commissions!D37 -> 11685
A9: Williams | B9: =Commissions!D39 -> 5980
A10: Wu | B10: =Commissions!D42 -> 11788
